---
chunk_id: discourse_topic_163247_post_87_00
source_url: https://discourse.onlinedegree.iitm.ac.in/t/163247/87
source_title: GA3 - Large Language Models - Discussion Thread [TDS Jan 2025]
content_type: discourse
tokens: 160
username: 22f3002723
post_number: 87
topic_id: 163247
---

## Post #87 by 22f3002723

**Direct Link**: [Post #87](https://discourse.onlinedegree.iitm.ac.in/t/163247/87)

For question 1 getting the below response … not sure what it means

ythonError: Traceback (most recent call last): File “/lib/python312.zip/_pyodide/_base.py”, line 523, in eval_code .run(globals, locals) ^^^^^^^^^^^^^^^^^^^^ File “/lib/python312.zip/_pyodide/_base.py”, line 357, in run coroutine = eval(self.code, globals, locals) ^^^^^^^^^^^^^^^^^^^^^^^^^^^^^^^^ File “”, line 53, in TypeError: unhashable type: ‘dict’
